Workbook

Sheet STATS & KPIs
B2: ='FORM A'!A6 -> CONTRACT : ZNT 1129 | F2: SUMMARY OF MONTHLY STATISTICS
J3: ='FORM A'!E6 -> OPERATOR : | K3: ='FORM A'!F6 -> Ripple Effect 40 (Pty) Ltd
B4: ='FORM A'!C3 -> PROVISION OF PUBLIC PASSENGER TRANSPORT MKUZE AND SURROUNDING
J5: ='FORM A'!E8 -> FOR MONTH : | K5: ='FORM A'!F8 -> 45778
D8: SUBSIDISED SERVICES | G8: UNSUBSIDISED SERVICES | J8: SUBTOTAL | M8: TOTAL
D9: Standard buses | E9: Maxi buses | F9: Train Buses | G9: Standard buses | H9: Maxi buses | I9: Train Buses | J9: Standard buses | K9: Maxi buses | L9: Train Buses | M9: All services & vehicles
B10: 1 | C10: Operational statistics
B11: 1.1 | C11: Number of buses operated | D11: =SUM(D12:D13) -> 38 | J11: =SUM(D11+G11) -> 38 | K11: =SUM(E11+H11) -> 0 | L11: =SUM(F11+I11) -> 0 | M11: =SUM(J11:L11) -> 38
C12: Peak vehicle requirement: | D12: 21 | J12: =SUM(D12+G12) -> 21 | K12: =SUM(E12+H12) -> 0 | L12: =SUM(F12+I12) -> 0 | M12: =SUM(J12:L12) -> 21
C13: Spare buses: | D13: 17 | J13: =SUM(D13+G13) -> 17 | K13: =SUM(E13+H13) -> 0 | L13: =SUM(F13+I13) -> 0 | M13: =SUM(J13:L13) -> 17
B14: 1.2 | C14: Number of routes operated | D14: =COUNT('FORM F1 SUB - STD BUS'!L17:L56) -> 40 | G14: =COUNT('FORM F2 UNSUB - STD BUS '!F17:F21) -> 5 | J14: =SUM(D14+G14) -> 45 | K14: =SUM(E14+H14) -> 0 | L14: =SUM(F14+I14) -> 0 | M14: =SUM(J14:L14) -> 45
B15: 1.3 | C15: Number of staff | D15: 0 | G15: 0 | J15: =SUM(D15+G15) -> 0 | K15: =SUM(E15+H15) -> 0 | L15: =SUM(F15+I15) -> 0 | M15: =SUM(J15:L15) -> 0
B16: 1.4 | C16: Number of trips scheduled | D16: ='FORM F1 SUB - STD BUS'!F58 -> 998 | G16: ='FORM F2 UNSUB - STD BUS '!F23 -> 164 | J16: =SUM(D16+G16) -> 1162 | K16: =SUM(E16+H16) -> 0 | L16: =SUM(F16+I16) -> 0 | M16: =SUM(J16:L16) -> 1162
B17: 1.5 | C17: Number of trips operated | D17: ='FORM F1 SUB - STD BUS'!K58 -> 996 | G17: ='FORM F2 UNSUB - STD BUS '!K23 -> 164 | J17: =SUM(D17+G17) -> 1160 | K17: =SUM(E17+H17) -> 0 | L17: =SUM(F17+I17) -> 0 | M17: =SUM(J17:L17) -> 1160
B18: 1.6 | C18: Kilometres scheduled | D18: ='FORM F1 SUB - STD BUS'!M58 -> 82763.4 | G18: ='FORM F2 UNSUB - STD BUS '!M23 -> 16345.2 | J18: =SUM(D18+G18) -> 99108.6 | K18: =SUM(E18+H18) -> 0 | L18: =SUM(F18+I18) -> 0 | M18: =SUM(J18:L18) -> 99108.6
B19: 1.7 | C19: Kilometres operated | D19: ='FORM F1 SUB - STD BUS'!N58 -> 82529.4 | G19: ='FORM F2 UNSUB - STD BUS '!N23 -> 16345.2 | J19: =SUM(D19+G19) -> 98874.6 | K19: =SUM(E19+H19) -> 0 | L19: =SUM(F19+I19) -> 0 | M19: =SUM(J19:L19) -> 98874.6
B20: 1.8 | C20: Standing kilometres claimed | D20: ='FORM F1 SUB - STD BUS'!Z58 -> 234 | G20: 0 | J20: =D20 -> 234 | K20: =E20 -> 0 | L20: =F20 -> 0 | M20: =SUM(J20:L20) -> 234
B21: 1.9 | C21: Total no of passengers conveyed | D21: =SUM(D22:D23) -> 58044 | G21: =SUM(G22:G23) -> 6635 | J21: =SUM(D21+G21) -> 64679 | K21: =SUM(E21+H21) -> 0 | L21: =SUM(F21+I21) -> 0 | M21: =SUM(J21:L21) -> 64679
C22: - Number of cash passengers conveyed | D22: ='FORM F1 SUB - STD BUS'!O58 -> 58044 | G22: ='FORM F2 UNSUB - STD BUS '!O23 -> 6635 | J22: =SUM(D22+G22) -> 64679 | K22: =SUM(E22+H22) -> 0 | L22: =SUM(F22+I22) -> 0 | M22: =SUM(J22:L22) -> 64679
C23: - Number of MJT passengers conveyed | D23: ='FORM F1 SUB - STD BUS'!P58 -> 0 | G23: ='FORM F2 UNSUB - STD BUS '!P23 -> 0 | J23: =SUM(D23+G23) -> 0 | K23: =SUM(E23+H23) -> 0 | L23: =SUM(F23+I23) -> 0 | M23: =SUM(J23:L23) -> 0
B26: 2 | C26: Revenue
B27: 2.1 | C27: Total passenger revenue | D27: =SUM(D28:D29) -> 1023296 | F27: =SUM(F28:F29) -> 0 | G27: =G28+G29 -> 92290.5 | I27: =SUM(I28:I29) -> 0 | J27: =SUM(D27+G27) -> 1115586.5 | K27: =SUM(E27+H27) -> 0 | L27: =SUM(F27+I27) -> 0 | M27: =SUM(J27:L27) -> 1115586.5
C28: - Income from cash passengers | D28: ='FORM F1 SUB - STD BUS'!S58 -> 1023296 | G28: ='FORM F2 UNSUB - STD BUS '!S23 -> 92290.5 | I28: 0 | J28: =SUM(D28+G28) -> 1115586.5 | K28: =SUM(E28+H28) -> 0 | L28: =SUM(F28+I28) -> 0 | M28: =SUM(J28:L28) -> 1115586.5
C29: - Income from MJT passengers | D29: ='FORM F1 SUB - STD BUS'!T58 -> 0 | G29: ='FORM F2 UNSUB - STD BUS '!T23 -> 0 | I29: 0 | J29: =SUM(D29+G29) -> 0 | K29: =SUM(E29+H29) -> 0 | L29: =SUM(F29+I29) -> 0 | M29: =SUM(J29:L29) -> 0
B30: 2.2 | C30: Income from private hires | D30: N/A | F30: N/A | I30: 0 | J30: =G30 -> 0 | K30: =H30 -> 0 | L30: =I30 -> 0 | M30: =SUM(J30:L30) -> 0
B31: 2.3 | C31: Income from dedicated contracts | D31: N/A | F31: N/A | I31: 0 | J31: =G31 -> 0 | K31: =H31 -> 0 | L31: =I31 -> 0 | M31: =SUM(J31:L31) -> 0
B32: 2.4 | C32: Subsidy claimed | D32: ='FORM A'!H15 -> 3308835 | I32: N/A | J32: =D32 -> 3308835 | K32: =E32 -> 0 | L32: =F32 -> 0 | M32: =SUM(J32:L32) -> 3308835
B33: 2.5 | C33: Total income | D33: =SUM(D28:D32) -> 4332131 | I33: =SUM(I28:I32) -> 0 | J33: =SUM(J28:J32) -> 4424421.5 | K33: =SUM(K28:K32) -> 0 | L33: =SUM(L28:L32) -> 0 | M33: =SUM(J33:L33) -> 4424421.5
B36: 3 | C36: Penalties | D36: Number | E36: % of penalties | F36: Value of penalties before escalation | G36: Escalation Factor* | H36: Total value of penalties including escalation
B37: 3.1 | C37: Total penalties | D37: ='FORM G2'!E35 -> 9 | E37: 0 | F37: ='FORM G2'!I35 -> 1889.34 | G37: ='FORM C'!#REF! -> #REF! | H37: =F37*G37 -> #REF!
B38: 3.2 | C38: Penalties for trips not operated | D38: =SUM('FORM G2'!E16:E18) -> 9 | E38: 0 | F38: =SUM('FORM G2'!I16:I18) -> 1889.34 | G38: =G37 -> #REF! | H38: =F38*G38 -> #REF! | I38: `
B39: 3.3 | C39: Penalties for time related offences | D39: =SUM('FORM G2'!E19:E21) -> 0 | E39: 0 | F39: =SUM('FORM G2'!I19:I21) -> 0 | G39: =G37 -> #REF! | H39: =F39*G39 -> #REF!
B40: 3.4 | C40: Penalties related to unsatisfactory vehicle condition | D40: =SUM('FORM G2'!E25:E28) -> 0 | E40: 0 | F40: =SUM('FORM G2'!I25:I28) -> 0 | G40: =G37 -> #REF! | H40: =F40*G40 -> #REF!
B41: 3.5 | C41: Penalties related to unroadworthy vehicles | D41: ='FORM G2'!E24 -> 0 | E41: 0 | F41: ='FORM G2'!I24 -> 0 | G41: =G37 -> #REF! | H41: =F41*G41 -> #REF!
B42: 3.6 | C42: Penalties related to stop & route adherence | D42: ='FORM G2'!E29+'FORM G2'!E31 -> 0 | E42: 0 | F42: ='FORM G2'!I29+'FORM G2'!I31 -> 0 | G42: =G37 -> #REF! | H42: =F42*G42 -> #REF!
B43: 3.7 | C43: Penalties related to duty & destination boards | D43: ='FORM G2'!E23 -> 0 | E43: 0 | F43: ='FORM G2'!I23 -> 0 | G43: =G37 -> #REF! | H43: =F43*G43 -> #REF!
B44: * Link to be changed monthly to reflect escalation factor applicable
B47: 4 | C47: DORA KPIs for subsidised services | D47: Inception values | E47: Output values | F47: Performance value (%)
B48: 4.1 | C48: Number of vehicles subsidised | D48: =+D12+E12+F12 -> 21 | E48: =D11+E11+F11 -> 38 | F48: =(E48-D48)/D48 -> 0.80952381
B49: 4.2 | C49: Number of subsidised routes operated | F49: =(E49-D49)/D49 -> #DIV/0!
...

Sheet FORM A
A1: FORM A
A3: PUBLIC TRANSPORT : | C3: PROVISION OF PUBLIC PASSENGER TRANSPORT MKUZE AND SURROUNDING
A6: CONTRACT : ZNT 1129 | E6: OPERATOR : | F6: Ripple Effect 40 (Pty) Ltd
A8: PAYMENT CERTIFICATE NO.: | C8: 320 | E8: FOR MONTH : | F8: 45778
A11: ACCUMULATED ESCALATED CONTRACT AMOUNT | E11: (FORM C, Col 7) | H11: =+'FORM C'!G337 -> 6.256782e+08
A13: LESS ACCUMULATED CERTIFICATE VALUES | E13: (FORM B, Col 5) | H13: ='FORM B'!E339 -> 6.2236936e+08
E15: SUB TOTAL 1 | H15: =SUM(H11-H13) -> 3308835
A20: DEDUCT REFUNDABLE PENALTIES IMPOSED FOR
A21: NON-COMPLIANCE WITH SERVICE SPECIFICATIONS :
A23: % FOR APPROVED VEHICLES NOT OPERATED (SCC - CL 5.5.8 (a)) | F23: 0
A25: % FOR TICKET MACHINES NOT USED (SCC - CL 5.5.9) | F25: 0
A27: % FOR MONTHLY STATISTICS NOT SUPPLIED (SCC - CL 5.5.9 (c)) | F27: 0
A29: % FOR FAILURE TO IMPLEMENT RDP PROPOSAL (SCC - CL5.510) | F29: 0
A31: % FOR FAILURE TO IMPLEMENT VIABLE SUB-CONTRACTING | F31: 0
E33: SUB TOTAL 2 | F33: =SUM(F18:F31) -> 0
A35: RELEASE REFUNDABLE PENALTIES IMPOSED FOR
A36: NON-COMPLIANCE WITH SERVICE SPECIFICATIONS :
A38: 5% FOR APPROVED VEHICLES NOT OPERATED (SCC - CL 5.5.8 (a)) | G38: 0
A40: 3% FOR APPROVED EE NOT USED (SCC - CL 5.5.9 (b)) | G40: 0
A42: 5% FOR MONTHLY STATISTICS NOT SUPPLIED (SCC - CL 5.5.9 (c)) | G42: 0
A44: 3% FOR FAILURE TO IMPLEMENT RDP PROPOSAL (SCC - CL5.5.10) | G44: 0
A46: 5% FOR FAILURE TO IMPLEMENT VIABLE SUB-CONTRACTING | G46: 0
E49: SUB TOTAL 3 | G49: =SUM(G38:G46) -> 0
A50: BANKDETAILS:
A51: Accountholder name: | B51: Ripple Effect 40 Close Corporation
A52: Account type: | B52: Cheque
A53: Account number: | B53: 50913212
A54: Bank: | B54: STANDARDBANK SA
A55: Branch name: | B55: KINGSMEAD
A56: Branch code: | B56: 40026
A59: TOTAL AMOUNT DUE | H59: =H15-F33+G49 -> 3308835
A62: On behalf of Ripple Effect 40 (PTY) LTD it is herewith certified that the information supplied in this
A63: Monthly Claim Form is correct and just.
A66: …………………………………………………………………………………………………… | G66: ………………………………..
A67: OPERATOR | G67: DATE
A69: …………………………………………………………………………………………………… | G69: ………………………………..
A70: CERTIFIED BY THE REPRESENTATIVE | G70: DATE
A73: ………………………………………………………………………………………………….. | G73: ………………………………..
A74: CERTIFIED : DEPARTMENT OF TRANSPORT | G74: DATE
A76: PAYMENT OF | B76: R.............................……… | D76: APPROVED BY
...

Sheet FORM B
A1: FORM B
A3: PUBLIC TRANSPORT : | C3: ='FORM A'!C3 -> PROVISION OF PUBLIC PASSENGER TRANSPORT MKUZE AND SURROUNDING
A5: ='FORM A'!A6 -> CONTRACT : ZNT 1129 | E5: OPERATOR : | F5: ='FORM A'!F6 -> Ripple Effect 40 (Pty) Ltd
A7: PAYMENT CERTIFICATE NO.: | C7: ='FORM A'!C8 -> 320 | E7: FOR MONTH : | F7: ='FORM A'!F8 -> 45778
A9: RECORD OF PAYMENTS | E9: ESTABLISHMENT COST PAID: | G9: 0
F11: Deduction of | G11: Release of | I11: Contributions
A12: Certificate | B12: Month | C12: Year | D12: Cert | E12: Accumulated | F12: refundable | G12: refundable | H12: Amounts | I12: paid to Bus
A13: number | D13: value | E13: certified values | F13: penalties or | G13: penalties or | H13: paid to | I13: Restructuring
F14: PTOG deductions | G14: PTOG deductions | H14: Operator | I14: Fund
A15: 1 | B15: 2 | C15: 3 | D15: 4 | E15: 5 | F15: 6 | G15: 7 | H15: 8 | I15: 9
A16: OLD PC SYSTEM PC ADJUST FOR REFUNDABLE PEN ETC. | E16: 5505132.4
A17: 1 | B17: November | C17: 1998 | D17: 663682.91 | E17: =D17 -> 663682.91 | H17: =D17 -> 663682.91
A18: =A17+1 -> 2 | B18: December | C18: 1998 | D18: 552711.48 | E18: =D18 -> 552711.48 | H18: =D18 -> 552711.48
A19: =A18+1 -> 3 | B19: January | C19: 1999 | D19: 636065.72 | E19: =D19 -> 636065.72 | H19: =D19 -> 636065.72
A20: =A19+1 -> 4 | B20: February | C20: 1999 | D20: 615122.13 | E20: =D20 -> 615122.13 | H20: =D20 -> 615122.13
A21: =A20+1 -> 5 | B21: March | C21: 1999 | D21: 687738.4 | E21: =D21 -> 687738.4 | H21: =D21 -> 687738.4
A22: =A21+1 -> 6 | B22: April | C22: 1999 | D22: 335237.7 | E22: =D22 -> 335237.7 | H22: =D22 -> 335237.7
A23: =A22+1 -> 7 | B23: May | C23: 1999 | D23: 606701.39 | E23: =D23 -> 606701.39 | H23: =D23 -> 606701.39
A24: =A23+1 -> 8 | B24: June | C24: 1999 | D24: 632266.31 | E24: =D24 -> 632266.31 | H24: =D24 -> 632266.31
A25: =A24+1 -> 9 | B25: July | C25: 1999 | D25: 861564.1 | E25: =D25 -> 861564.1 | H25: =D25 -> 861564.1
A26: =A25+1 -> 10 | B26: August | C26: 1999 | D26: 694941.72 | E26: =D26 -> 694941.72 | H26: =D26 -> 694941.72
A27: =A26+1 -> 11 | B27: September | C27: 1999 | D27: 753476.86 | E27: =D27 -> 753476.86 | H27: =D27 -> 753476.86
A28: =A27+1 -> 12 | B28: October | C28: 1999 | D28: 691530.92 | E28: =D28 -> 691530.92 | H28: =D28 -> 691530.92
A29: =A28+1 -> 13 | B29: November | C29: 1999 | D29: 778922.04 | E29: =D29 -> 778922.04 | H29: =D29 -> 778922.04
... A256: =A255+1 -> 240 | B256: September | C256: 2018 | D256: 2712031.3 | E256: =D256 -> 2712031.3 | H256: =D256 -> 2712031.3
A257: =A256+1 -> 241 | B257: October | C257: 2018 | D257: 2554974.2 | E257: =D257 -> 2554974.2 | H257: =D257 -> 2554974.2 | J257: Penalties deducted INCORRECTLY in JUNE
A258: =A257+1 -> 242 | B258: November | C258: 2018 | D258: 2856222.3 | E258: =D258 -> 2856222.3 | H258: =D258 -> 2856222.3
A259: =A258+1 -> 243 | B259: December | C259: 2018 | D259: 2797098.2 | E259: =D259 -> 2797098.2 | H259: =D259 -> 2797098.2 | J259: 45089 | K259: 5 | L259: 15 | M259: 1100 | N259: 0.45833333 | O259: MKUZE | P259: MKUZE | Q259: EKUKHANYENI | R259: 4 | S259: 117 | T259: 8.21 | U259: 0.4 | V259: =ROUND(S259*T259*U259,2) -> 384.23
A260: =A259+1 -> 244 | B260: January | C260: 2019 | D260: 2609454.3 | E260: =D260 -> 2609454.3 | H260: =D260 -> 2609454.3 | J260: 45089 | K260: 1B.1 | L260: 1 | M260: 1100 | N260: 0.45833333 | O260: MKUZE | P260: MKUZE | Q260: EMACHOBENI | R260: 4 | S260: 90 | T260: 8.21 | U260: 0.4 | V260: =ROUND(S260*T260*U260,2) -> 295.56
A261: =A260+1 -> 245 | B261: February | C261: 2019 | D261: 2417774.9 | E261: =D261 -> 2417774.9 | H261: =D261 -> 2417774.9 | J261: 45089 | K261: 7A | L261: 21 | M261: 1100 | N261: 0.45833333 | O261: MKUZE | P261: MKUZE | Q261: MANGUZE | R261: 4 | S261: 136.5 | T261: 8.21 | U261: 0.4 | V261: =ROUND(S261*T261*U261,2) -> 448.27
A262: =A261+1 -> 246 | B262: March | C262: 2019 | D262: 2566595.1 | E262: =D262 -> 2566595.1 | H262: =D262 -> 2566595.1 | J262: 45089 | K262: 6A | L262: 17 | M262: 1200 | N262: 0.5 | O262: MKUZE | P262: MKUZE | Q262: MANGUZE | R262: 4 | S262: 149.9 | T262: 8.21 | U262: 0.4 | V262: =ROUND(S262*T262*U262,2) -> 492.27
A263: =A262+1 -> 247 | B263: April | C263: 2019 | D263: 2638118.5 | E263: =D263 -> 2638118.5 | H263: =D263 -> 2638118.5 | J263: 45089 | K263: 9A | L263: 25 | M263: 1200 | N263: 0.5 | O263: MKUZE | P263: MKUZE | Q263: MAZIBUKO | R263: 4 | S263: 70.3 | T263: 8.21 | U263: 0.4 | V263: =ROUND(S263*T263*U263,2) -> 230.87
A264: =A263+1 -> 248 | B264: May | C264: 2019 | D264: 2768870.1 | E264: =D264 -> 2768870.1 | H264: =D264 -> 2768870.1 | J264: 45089 | K264: 8 | L264: 24mth | M264: 1230 | N264: 0.52083333 | O264: MKUZE | P264: MKUZE | Q264: MANABA | R264: 4 | S264: 78.8 | T264: 8.21 | U264: 0.4 | V264: =ROUND(S264*T264*U264,2) -> 258.78
A265: =A264+1 -> 249 | B265: June | C265: 2019 | D265: 2751264.1 | E265: =D265 -> 2751264.1 | H265: =D265 -> 2751264.1 | J265: 45089 | K265: 1A4 | L265: 19 | M265: 1300 | N265: 0.54166667 | O265: MKUZE | P265: MKUZE | Q265: MAVELA | R265: 4 | S265: 35.8 | T265: 8.21 | U265: 0.4 | V265: =ROUND(S265*T265*U265,2) -> 117.57
A266: =A265+1 -> 250 | B266: July | C266: 2019 | D266: 2729541.8 | E266: =D266 -> 2729541.8 | H266: =D266 -> 2729541.8 | J266: 45089 | K266: 7C | L266: 22 | M266: 1300 | N266: 0.54166667 | O266: MKUZE | P266: MKUZE | Q266: NGUTSHANA | R266: 4 | S266: 117.5 | T266: 8.21 | U266: 0.4 | V266: =ROUND(S266*T266*U266,2) -> 385.87
A267: =A266+1 -> 251 | B267: August | C267: 2019 | D267: 2738515.6 | E267: =D267 -> 2738515.6 | H267: =D267 -> 2738515.6 | J267: 45089 | K267: 1A1 | L267: 2 | M267: 1400 | N267: 0.58333333 | O267: MKUZE | P267: MKUZE | Q267: EMACHOBENI | R267: 4 | S267: 90 | T267: 8.21 | U267: 0.4 | V267: =ROUND(S267*T267*U267,2) -> 295.56
A268: =A267+1 -> 252 | B268: September | C268: 2019 | D268: 2780375.1 | E268: =D268 -> 2780375.1 | H268: =D268 -> 2780375.1 | J268: 45089 | K268: 9B | L268: 26 | M268: 1400 | N268: 0.58333333 | O268: MKUZE | P268: MKUZE | Q268: HLABISA | R268: 4 | S268: 78 | T268: 8.21 | U268: 0.4 | V268: =ROUND(S268*T268*U268,2) -> 256.15
A269: =A268+1 -> 253 | B269: October | C269: 2019 | D269: 2634787.8 | E269: =D269 -> 2634787.8 | H269: =D269 -> 2634787.8 | J269: 45089 | K269: 6B | L269: 18 | M269: 1640 | N269: 0.69444444 | O269: MKUZE | P269: MKUZE | Q269: MBUYISA | R269: 4 | S269: 97.5 | T269: 8.21 | U269: 0.4 | V269: =ROUND(S269*T269*U269,2) -> 320.19
A270: =A269+1 -> 254 | B270: November | C270: 2019 | D270: 2776691.6 | E270: =D270 -> 2776691.6 | H270: =D270 -> 2776691.6 | J270: 45089 | K270: 6C | L270: 19 | M270: 1730 | N270: 0.72916667 | O270: MKUZE | P270: MKUZE | Q270: JOZINI | R270: 4 | S270: 41 | T270: 8.21 | U270: 0.4 | V270: =ROUND(S270*T270*U270,2) -> 134.64
A271: =A270+1 -> 255 | B271: December | C271: 2019 | D271: 2646984.4 | E271: =D271 -> 2646984.4 | H271: =D271 -> 2646984.4 | J271: 45090 | K271: 1B2 | L271: 3 | M271: 600 | N271: 0.36111111 | O271: MKUZE | P271: MKUZE | Q271: INGWAVUMA | R271: 4 | S271: 85.3 | T271: 8.21 | U271: 0.4 | V271: =ROUND(S271*T271*U271,2) -> 280.13
...

Sheet FORM C
A1: FORM C
A3: PUBLIC TRANSPORT : | C3: ='FORM A'!C3 -> PROVISION OF PUBLIC PASSENGER TRANSPORT MKUZE AND SURROUNDING
A5: ='FORM A'!A6 -> CONTRACT : ZNT 1129 | E5: OPERATOR : | F5: ='FORM A'!F6 -> Ripple Effect 40 (Pty) Ltd
A7: PAYMENT CERTIFICATE NO: | C7: ='FORM A'!C8 -> 320 | E7: FOR MONTH : | F7: ='FORM A'!F8 -> 45778
A9: ESCALATED MONTHLY CERTIFICATE
A12: Certificate | B12: Month | C12: Year | D12: Amount for | E12: Escalation | F12: Escalated | G12: Accumulated
A13: number | D13: Escalation | E13: Factor * | F13: Amount | G13: Total
D14: (Form E) | E14: (Form D) | F14: (4 x 5)
A15: 1 | B15: 2 | C15: 3 | D15: 4 | E15: 5 | F15: 6 | G15: 7
A16: 1 | B16: November | C16: 1998 | D16: 653079.7 | E16: ='FORM D'!G22 -> 1.025043 | F16: =ROUND(D16*E16,2) -> 669434.77 | G16: =SUM($F$16:F16) -> 669434.77
A17: =A16+1 -> 2 | B17: December | C17: 1998 | D17: 543881.18 | E17: ='FORM D'!G23 -> 1.018293 | F17: =ROUND(D17*E17,2) -> 553830.37 | G17: =SUM($F$16:F17) -> 1223265.1
A18: =A17+1 -> 3 | B18: January | C18: 1999 | D18: 626903.73 | E18: ='FORM D'!G24 -> 1.0186755 | F18: =ROUND(D18*E18,2) -> 638611.48 | G18: =SUM($F$16:F18) -> 1861876.6
A19: =A18+1 -> 4 | B19: February | C19: 1999 | D19: 600141.48 | E19: ='FORM D'!G25 -> 1.0301078 | F19: =ROUND(D19*E19,2) -> 618210.4 | G19: =SUM($F$16:F19) -> 2480087
A20: =A19+1 -> 5 | B20: March | C20: 1999 | D20: 575610.42 | E20: ='FORM D'!G26 -> 1.0293972 | F20: =ROUND(D20*E20,2) -> 592531.78 | G20: =SUM($F$16:F20) -> 3072618.8
A21: =A20+1 -> 6 | B21: April | C21: 1999 | D21: 399087.15 | E21: ='FORM D'!G27 -> 1.0480167 | F21: =ROUND(D21*E21,2) -> 418250 | G21: =SUM($F$16:F21) -> 3490868.8
A22: =A21+1 -> 7 | B22: May | C22: 1999 | D22: 594897.07 | E22: ='FORM D'!G28 -> 1.0626464 | F22: =ROUND(D22*E22,2) -> 632165.2 | G22: =SUM($F$16:F22) -> 4123034
A23: =A22+1 -> 8 | B23: June | C23: 1999 | D23: 655391 | E23: ='FORM D'!G29 -> 1.0697517 | F23: =ROUND(D23*E23,2) -> 701105.61 | G23: =SUM($F$16:F23) -> 4824139.6
A24: =A23+1 -> 9 | B24: July | C24: 1999 | D24: 664456.02 | E24: ='FORM D'!G30 -> 1.0933768 | F24: =ROUND(D24*E24,2) -> 726500.78 | G24: =SUM($F$16:F24) -> 5550640.4
A25: =A24+1 -> 10 | B25: August | C25: 1999 | D25: 632628.93 | E25: ='FORM D'!G31 -> 1.1097463 | F25: =ROUND(D25*E25,2) -> 702057.61 | G25: =SUM($F$16:F25) -> 6252698
A26: =A25+1 -> 11 | B26: September | C26: 1999 | D26: 633492.4 | E26: ='FORM D'!G32 -> 1.1236016 | F26: =ROUND(D26*E26,2) -> 711793.1 | G26: =SUM($F$16:F26) -> 6964491.1
A27: =A26+1 -> 12 | B27: October | C27: 1999 | D27: 664346.15 | E27: ='FORM D'!G33 -> 1.1356807 | F27: =ROUND(D27*E27,2) -> 754485.08 | G27: =SUM($F$16:F27) -> 7718976.2
A28: =A27+1 -> 13 | B28: November | C28: 1999 | D28: 676326.7 | E28: ='FORM D'!G34 -> 1.1445623 | F28: =ROUND(D28*E28,2) -> 774098.05 | G28: =SUM($F$16:F28) -> 8493074.2
... A275: =A274+1 -> 260 | B275: May | C275: 2020 | D275: 600823.58 | E275: ='FORM D'!G281 -> 3.722718 | F275: =ROUND(D275*E275,2) -> 2236696.8 | G275: =SUM($F$16:F275) -> 4.3428784e+08
A276: 261 | B276: June | C276: 2020 | D276: 647117.67 | E276: ='FORM D'!G282 -> 3.744892 | F276: =ROUNDUP(D276*E276,2) -> 2423385.8 | G276: =SUM($F$16:F276) -> 4.3671123e+08
A277: 262 | B277: July | C277: 2020 | D277: 646491.71 | E277: ='FORM D'!G283 -> 3.939529 | F277: =ROUND(D277*E277,2) -> 2546872.8 | G277: =SUM($F$16:F277) -> 4.392581e+08
A278: 263 | B278: August | C278: 2020 | D278: 661473.12 | E278: ='FORM D'!G284 -> 3.991268 | F278: =ROUND(D278*E278,2) -> 2640116.5 | G278: =SUM($F$16:F278) -> 4.4189822e+08
A279: 264 | B279: September | C279: 2020 | D279: 653254.93 | E279: ='FORM D'!G285 -> 3.966631 | F279: =ROUND(D279*E279,2) -> 2591221.3 | G279: =SUM($F$16:F279) -> 4.4448944e+08
A280: 265 | B280: October | C280: 2020 | D280: 678400.67 | E280: ='FORM D'!G286 -> 3.863152 | F280: =ROUND(D280*E280,2) -> 2620764.9 | G280: =SUM($F$16:F280) -> 4.471102e+08 | I280: Penalty Corrections - March 2021
A281: 266 | B281: November | C281: 2020 | D281: 656623.74 | E281: ='FORM D'!G287 -> 3.850834 | F281: =ROUND(D281*E281,2) -> 2528549 | G281: =SUM($F$16:F281) -> 4.4963875e+08 | I281: Original March 2021 Amount for Escalation | J281: Penalties | K281: Adjusted Amount for Escalation
A282: 267 | B282: December | C282: 2020 | D282: 693510.16 | E282: ='FORM D'!G288 -> 3.873008 | F282: =ROUND(D282*E282,2) -> 2685970.4 | G282: =SUM($F$16:F282) -> 4.5232472e+08
A283: 268 | B283: January | C283: 2021 | D283: 651715.2 | E283: ='FORM D'!G289 -> 3.934602 | F283: =ROUND(D283*E283,2) -> 2564239.9 | G283: =SUM($F$16:F283) -> 4.5488896e+08 | I283: 684003.84 | J283: -6674.16 | K283: =I283+J283 -> 677329.68
A284: 269 | B284: February | C284: 2021 | D284: 629066.58 | E284: ='FORM D'!G290 -> 4.001123 | F284: =ROUND(D284*E284,2) -> 2516972.8 | G284: =SUM($F$16:F284) -> 4.5740593e+08
A285: 270 | B285: March | C285: 2021 | D285: 677329.68 | E285: ='FORM D'!G291 -> 4.065181 | F285: =ROUND(D285*E285,2) -> 2753467.8 | G285: =SUM($F$16:F285) -> 4.601594e+08
A286: 271 | B286: April | C286: 2021 | D286: 661593.74 | E286: ='FORM D'!G292 -> 4.136631 | F286: =ROUND(D286*E286,2) -> 2736769.2 | G286: =SUM($F$16:F286) -> 4.6289617e+08
A287: 272 | B287: May | C287: 2021 | D287: 664256.87 | E287: ='FORM D'!G293 -> 4.102138 | F287: =ROUND(D287*E287,2) -> 2724873.4 | G287: =SUM($F$16:F287) -> 4.6562104e+08 | I287: Public Holiday Corrections - December 2021
A288: 273 | B288: June | C288: 2021 | D288: 648082.28 | E288: ='FORM D'!G294 -> 4.126776 | F288: =ROUND(D288*E288,2) -> 2674490.4 | G288: =SUM($F$16:F288) -> 4.6829553e+08 | I288: Original November 2021 Amount for Escalation | J288: Correction Amount | K288: Adjusted Amount for Escalation
A289: 274 | B289: July | C289: 2021 | D289: 634633.74 | E289: ='FORM D'!G295 -> 4.251699 | F289: =ROUND(D289*E289,2) -> 2698271.6 | G289: =SUM($F$16:F289) -> 4.7099381e+08
A290: 275 | B290: August | C290: 2021 | D290: 665412.64 | E290: ='FORM D'!G296 -> 4.313293 | F290: =ROUND(D290*E290,2) -> 2870119.7 | G290: =SUM($F$16:F290) -> 4.7386393e+08 | I290: 674246.78 | J290: -17606.35 | K290: 656640.43
A291: 276 | B291: September | C291: 2021 | D291: 658666.33 | E291: ='FORM D'!G297 -> 4.29851 | F291: =ROUND(D291*E291,2) -> 2831283.8 | G291: =SUM($F$16:F291) -> 4.7669521e+08
A292: 277 | B292: October | C292: 2021 | D292: 670057.38 | E292: ='FORM D'!G298 -> 4.323148 | F292: =ROUND(D292*E292,2) -> 2896757.2 | G292: =SUM($F$16:F292) -> 4.7959197e+08
...

Sheet FORM D
D1: FORM D
A3: PUBLIC TRANSPORT : | C3: ='FORM A'!C3 -> PROVISION OF PUBLIC PASSENGER TRANSPORT MKUZE AND SURROUNDING
A5: ='FORM A'!A6 -> CONTRACT : ZNT 1129 | E5: OPERATOR : | F5: ='FORM A'!F6 -> Ripple Effect 40 (Pty) Ltd
A7: PAYMENT CERTIFICATE NO : | C7: ='FORM A'!C8 -> 320 | E7: FOR MONTH : | F7: ='FORM C'!F7 -> 45778
A9: ESCALATION FORMULA (REFER GCC CLAUSE 37)
A10: INDICES WEIGHTED AVERAGE : | E10: BASE MONTH = | F10: 36039
A12: f = (1-x) ((a x (Lt/Lo + b x (Bt/Bo) + (c x Ft/ Fo) - 1)
A14: with
A15: x = | B15: 0.15 | D15: Lo | E15: 19 | F15: SEIFSA
A16: a = | B16: 0.35
A17: b = | B17: 0.45 | D17: Bo | E17: 49.4 | F17: Bus & Truck Index (PPI Report)
A18: c = | B18: 0.2
D19: Fo | E19: 6.9 | F19: Fuel Index (PPI Report)
A21: CERT NO. | B21: MONTH | C21: YEAR | D21: Lt | E21: Bt | F21: Ft | G21: f + 1
A22: 1 | B22: November | C22: 1998 | D22: 19.528979 | E22: 50.9 | F22: 7.1088644 | G22: =((1-$B$15)*(($B$16*D22/$E$15)+($B$17*E22/$E$17)+($B$18*F22/$E$19)-1))+1 -> 1.025043
A23: =A22+1 -> 2 | B23: December | C23: 1998 | D23: 19.528979 | E23: 50.9 | F23: 6.8348919 | G23: =((1-$B$15)*(($B$16*D23/$E$15)+($B$17*E23/$E$17)+($B$18*F23/$E$19)-1))+1 -> 1.018293
A24: =A23+1 -> 3 | B24: January | C24: 1999 | D24: 19.528979 | E24: 51.5 | F24: 6.6618567 | G24: =((1-$B$15)*(($B$16*D24/$E$15)+($B$17*E24/$E$17)+($B$18*F24/$E$19)-1))+1 -> 1.0186755
A25: =A24+1 -> 4 | B25: February | C25: 1999 | D25: 19.528979 | E25: 51.6 | F25: 7.0944448 | G25: =((1-$B$15)*(($B$16*D25/$E$15)+($B$17*E25/$E$17)+($B$18*F25/$E$19)-1))+1 -> 1.0301078
A26: =A25+1 -> 5 | B26: March | C26: 1999 | D26: 19.528979 | E26: 51.6 | F26: 7.0656056 | G26: =((1-$B$15)*(($B$16*D26/$E$15)+($B$17*E26/$E$17)+($B$18*F26/$E$19)-1))+1 -> 1.0293972
A27: =A26+1 -> 6 | B27: April | C27: 1999 | D27: 19.528979 | E27: 53.5 | F27: 7.2242212 | G27: =((1-$B$15)*(($B$16*D27/$E$15)+($B$17*E27/$E$17)+($B$18*F27/$E$19)-1))+1 -> 1.0480167
A28: =A27+1 -> 7 | B28: May | C28: 1999 | D28: 19.528979 | E28: 53.6 | F28: 7.7865857 | G28: =((1-$B$15)*(($B$16*D28/$E$15)+($B$17*E28/$E$17)+($B$18*F28/$E$19)-1))+1 -> 1.0626464
A29: =A28+1 -> 8 | B29: June | C29: 1999 | D29: 19.528979 | E29: 53.6 | F29: 8.0749778 | G29: =((1-$B$15)*(($B$16*D29/$E$15)+($B$17*E29/$E$17)+($B$18*F29/$E$19)-1))+1 -> 1.0697517
A30: =A29+1 -> 9 | B30: July | C30: 1999 | D30: 20.742849 | E30: 53.6 | F30: 8.2624326 | G30: =((1-$B$15)*(($B$16*D30/$E$15)+($B$17*E30/$E$17)+($B$18*F30/$E$19)-1))+1 -> 1.0933768
A31: =A30+1 -> 10 | B31: August | C31: 1999 | D31: 20.742849 | E31: 54.2 | F31: 8.7382796 | G31: =((1-$B$15)*(($B$16*D31/$E$15)+($B$17*E31/$E$17)+($B$18*F31/$E$19)-1))+1 -> 1.1097463
A32: =A31+1 -> 11 | B32: September | C32: 1999 | D32: 20.742849 | E32: 54.2 | F32: 9.3006441 | G32: =((1-$B$15)*(($B$16*D32/$E$15)+($B$17*E32/$E$17)+($B$18*F32/$E$19)-1))+1 -> 1.1236016
A33: =A32+1 -> 12 | B33: October | C33: 1999 | D33: 20.742849 | E33: 54.2 | F33: 9.7909106 | G33: =((1-$B$15)*(($B$16*D33/$E$15)+($B$17*E33/$E$17)+($B$18*F33/$E$19)-1))+1 -> 1.1356807
A34: =A33+1 -> 13 | B34: November | C34: 1999 | D34: 20.742849 | E34: 54.2 | F34: 10.151401 | G34: =((1-$B$15)*(($B$16*D34/$E$15)+($B$17*E34/$E$17)+($B$18*F34/$E$19)-1))+1 -> 1.1445623
... A280: =A279+1 -> 259 | B280: April | C280: 2020 | D280: 85.194906 | E280: 129.4 | F280: 57.5 | G280: =((1-$B$15)*(($B$16*D280/$E$15)+($B$17*E280/$E$17)+($B$18*F280/$E$19)-1))+1 -> 3.9025727
A281: =A280+1 -> 260 | B281: May | C281: 2020 | D281: 85.194906 | E281: 129.4 | F281: 50.2 | G281: =ROUND(((1-$B$15)*(($B$16*D281/$E$15)+($B$17*E281/$E$17)+($B$18*F281/$E$19)-1))+1,6) -> 3.722718
A282: 261 | B282: June | C282: 2020 | D282: 85.194906 | E282: 129.4 | F282: 51.1 | G282: =ROUND(((1-$B$15)*(($B$16*D282/$E$15)+($B$17*E282/$E$17)+($B$18*F282/$E$19)-1))+1,6) -> 3.744892
A283: 262 | B283: July | C283: 2020 | D283: 85.194906 | E283: 129.4 | F283: 59 | G283: =ROUND(((1-$B$15)*(($B$16*D283/$E$15)+($B$17*E283/$E$17)+($B$18*F283/$E$19)-1))+1,6) -> 3.939529
A284: 263 | B284: August | C284: 2020 | D284: 85.194906 | E284: 129.4 | F284: 61.1 | G284: =ROUND(((1-$B$15)*(($B$16*D284/$E$15)+($B$17*E284/$E$17)+($B$18*F284/$E$19)-1))+1,6) -> 3.991268
A285: 264 | B285: September | C285: 2020 | D285: 85.194906 | E285: 129.4 | F285: 60.1 | G285: =ROUND(((1-$B$15)*(($B$16*D285/$E$15)+($B$17*E285/$E$17)+($B$18*F285/$E$19)-1))+1,6) -> 3.966631
A286: 265 | B286: October | C286: 2020 | D286: 85.194906 | E286: 129.4 | F286: 55.9 | G286: =ROUND(((1-$B$15)*(($B$16*D286/$E$15)+($B$17*E286/$E$17)+($B$18*F286/$E$19)-1))+1,6) -> 3.863152
A287: 266 | B287: November | C287: 2020 | D287: 85.194906 | E287: 129.4 | F287: 55.4 | G287: =ROUND(((1-$B$15)*(($B$16*D287/$E$15)+($B$17*E287/$E$17)+($B$18*F287/$E$19)-1))+1,6) -> 3.850834
A288: 267 | B288: December | C288: 2020 | D288: 85.194906 | E288: 129.4 | F288: 56.3 | G288: =ROUND(((1-$B$15)*(($B$16*D288/$E$15)+($B$17*E288/$E$17)+($B$18*F288/$E$19)-1))+1,6) -> 3.873008
A289: 268 | B289: January | C289: 2021 | D289: 85.194906 | E289: 129.4 | F289: 58.8 | G289: =ROUND(((1-$B$15)*(($B$16*D289/$E$15)+($B$17*E289/$E$17)+($B$18*F289/$E$19)-1))+1,6) -> 3.934602
A290: 269 | B290: February | C290: 2021 | D290: 85.194906 | E290: 129.4 | F290: 61.5 | G290: =ROUND(((1-$B$15)*(($B$16*D290/$E$15)+($B$17*E290/$E$17)+($B$18*F290/$E$19)-1))+1,6) -> 4.001123
A291: 270 | B291: March | C291: 2021 | D291: 85.194906 | E291: 129.4 | F291: 64.1 | G291: =ROUND(((1-$B$15)*(($B$16*D291/$E$15)+($B$17*E291/$E$17)+($B$18*F291/$E$19)-1))+1,6) -> 4.065181
A292: 271 | B292: April | C292: 2021 | D292: 85.194906 | E292: 129.4 | F292: 67 | G292: =ROUND(((1-$B$15)*(($B$16*D292/$E$15)+($B$17*E292/$E$17)+($B$18*F292/$E$19)-1))+1,6) -> 4.136631
...

Sheet FORM E
A1: FORM E
B2: REQUEST FOR MONTHLY PAYMENT
B4: The Representative
B6: For Attention : | C6: Petrus Ackerman
B8: PUBLIC TRANSPORT : | D8: ='FORM A'!C3 -> PROVISION OF PUBLIC PASSENGER TRANSPORT MKUZE AND SURROUNDING
B10: ='FORM A'!A6 -> CONTRACT : ZNT 1129 | E10: OPERATOR : | F10: ='FORM A'!F6 -> Ripple Effect 40 (Pty) Ltd
B12: PAYMENT CERTIFICATE NO.: | D12: =+'FORM A'!C8 -> 320 | E12: FOR MONTH : | F12: ='FORM A'!F8 -> 45778
K14: FORM 9 - SCHEDULE OF QUANTITIES
B15: Enclosed Schedule Form F from 1 to 31 May 2025 for the above contract
B17: Total scheduled revenue kms = | D17: ='FORM F1 SUB - STD BUS'!M58 -> 82763.4 | M17: Rates | N17: Months | O17: Kms | P17: Rand Value
B19: The total non-escalated amount claimed for this month is made up as follows : | J19: 1 | K19: 20301 | L19: 4.58
J20: 2 | K20: 19300 | L20: 4.82
A21: OPERATED KM: | J21: 3 | K21: 18300 | L21: 5.08
J22: 4 | K22: 17300 | L22: 5.38
B23: A. Bus | C23: ='FORM F1 SUB - STD BUS'!N58 -> 82529.4 | D23: Revenue kms at contract rate | F23: =IF(D17>95000,7.11,IF(D17>90000,7.32,IF(D17>85000,7.59,IF(D17>80000,8.21,IF(D17>75000,8.75,IF(D17>70000,9.35)))))) -> 8.21 | G23: = | H23: =ROUND(C23*F23,2) -> 677566.37 | J23: 5 | K23: 0 | L23: 5.38
O24: TOTAL | P24: =SUM(#REF!) -> #REF!
D25: SUBTOTAL | H25: =SUM(H23:H23) -> 677566.37 | J25: =F23*1.5 -> 12.315
A27: STANDING KM:
B29: A. Bus | C29: ='FORM F1 SUB - STD BUS'!Z58 -> 234 | D29: kms at contract rate | F29: =ROUND(F23*0.6,2) -> 4.93 | G29: = | H29: =ROUND(C29*F29,2) -> 1153.62 | J29: =F23*0.6 -> 4.926
B32: Less non-refundable penalties imposed for not operating in accordance with
B33: the contract specifications :
B35: GCC Clause 21 and SCC Clause 5, from FORM G | G35: = | H35: ='FORM G2'!I35 -> 1889.34
D39: TOTAL carried to Form C (Col 4) for escalation | H39: =SUM(H25:H29)-H35 -> 676830.65
B43: Signed on behalf of Operator: | D43: ='FORM A'!F6 -> Ripple Effect 40 (Pty) Ltd
B47: Signature | G47: Date:
B51: Approval of claim by Representative
B54: Signature | F54: Date

Sheet FORM H
A1: FORM H
A3: PUBLIC TRANSPORT : | C3: ='FORM A'!C3 -> PROVISION OF PUBLIC PASSENGER TRANSPORT MKUZE AND SURROUNDING
A5: ='FORM A'!A6 -> CONTRACT : ZNT 1129 | F5: OPERATOR : | G5: ='FORM A'!F6 -> Ripple Effect 40 (Pty) Ltd
A7: PAYMENT CERTIFICATE NO.: | D7: ='FORM A'!C8 -> 320 | F7: FOR MONTH : | G7: ='FORM A'!F8 -> 45778
A9: BUDGET CONTRACT EXPENDITURE FORM
F10: FINANCIAL YEAR:
F11: SUBSIDY ALLOCATION:
D14: Kilometres | F14: Monthly Subsidy
A16: Certificate | B16: Month | C16: Year | D16: Scheduled | E16: Operated | F16: Budgeted | G16: Monies | H16: Monies | I16: Balance | K16: PTOG
A17: No. | G17: Claimed | H17: Paid | K17: Refund Claimed
A19: 1 | B19: 2 | C19: 3 | D19: 4 | E19: 5 | F19: 6 | G19: 7 | H19: 8 | I19: 9
A20: 22 | B20: August | C20: 2000 | G20: ='FORM B'!H38 -> 782646.53
A21: =A20+1 -> 23 | B21: September | C21: 2000 | G21: ='FORM B'!H39 -> 888930.16
A22: =A21+1 -> 24 | B22: October | C22: 2000 | G22: ='FORM B'!H40 -> 902304.65
A23: =A22+1 -> 25 | B23: November | C23: 2000 | G23: ='FORM B'!H41 -> 795334.02
A24: =A23+1 -> 26 | B24: December | C24: 2000 | G24: ='FORM B'!H42 -> 783205.09
A25: =A24+1 -> 27 | B25: January | C25: 2001 | G25: ='FORM B'!H43 -> 470298.4
A26: =A25+1 -> 28 | B26: February | C26: 2001 | G26: ='FORM B'!H44 -> 319622.65
A27: =A26+1 -> 29 | B27: March | C27: 2001 | G27: ='FORM B'!H45 -> 648587.46
A28: =A27+1 -> 30 | B28: April | C28: 2001 | G28: ='FORM B'!H46 -> 657436.78
A29: =A28+1 -> 31 | B29: May | C29: 2001 | G29: ='FORM B'!H47 -> 657436.78
A30: 32 | B30: May | C30: 2001 | G30: ='FORM B'!H48 -> 112530.6
A31: =A30+1 -> 33 | B31: June | C31: 2001 | G31: ='FORM B'!H49 -> 564446.96
A32: =A31+1 -> 34 | B32: July | C32: 2001 | G32: ='FORM B'!H50 -> 704751.57
A33: =A32+1 -> 35 | B33: August | C33: 2001 | G33: ='FORM B'!H51 -> 820266.15
A34: =A33+1 -> 36 | B34: September | C34: 2001 | G34: ='FORM B'!H52 -> -58633.52
A35: =A34+1 -> 37 | B35: October | C35: 2001 | G35: ='FORM B'!H53 -> 4211.92
A36: =A35+1 -> 38 | B36: November | C36: 2001 | G36: ='FORM B'!H54 -> 354016.29
A37: =A36+1 -> 39 | B37: December | C37: 2002 | G37: ='FORM B'!H55 -> 923872.94
A38: =A37+1 -> 40 | B38: January | C38: 2002 | G38: ='FORM B'!H56 -> 950628.74
A39: =A38+1 -> 41 | B39: February | C39: 2002 | G39: ='FORM B'!H57 -> 991401.45
A40: =A39+1 -> 42 | B40: March | C40: 2002 | G40: ='FORM B'!H58 -> 997903.87
A41: =A40+1 -> 43 | B41: April | C41: 2002 | G41: ='FORM B'!H59 -> 965310.04
A42: =A41+1 -> 44 | B42: May | C42: 2002 | G42: ='FORM B'!H60 -> 1104643.1
... A64: =A63+1 -> 66 | B64: March | C64: 2004 | G64: ='FORM B'!H82 -> 1009176.1
A65: =A64+1 -> 67 | B65: April | C65: 2004 | D65: 82921 | E65: 82761.203 | G65: ='FORM B'!H83 -> 1178064.2
A66: =A65+1 -> 68 | B66: May | C66: 2004 | D66: 80209.102 | E66: 79858.5 | G66: ='FORM B'!H84 -> 1029890.6
A67: =A66+1 -> 69 | B67: June | C67: 2004 | D67: 84907.898 | E67: 84739.898 | G67: ='FORM B'!H85 -> 991602.66
A68: =A67+1 -> 70 | B68: July | C68: 2004 | D68: 81169 | E68: 81128 | G68: ='FORM B'!H86 -> 1124215.7
A69: =A68+1 -> 71 | B69: August | C69: 2004 | D69: 80366.703 | E69: 80296.398 | G69: ='FORM B'!H87 -> 1035409.2
...

Sheet FORM F1 SUB - STD BUS
B1: FORM F1 - STANDARD BUS
B3: PUBLIC TRANSPORT : | E3: ='FORM A'!C3 -> PROVISION OF PUBLIC PASSENGER TRANSPORT MKUZE AND SURROUNDING
B5: ='FORM B'!A5 -> CONTRACT : ZNT 1129 | M5: OPERATOR : | O5: ='FORM A'!F6 -> Ripple Effect 40 (Pty) Ltd
B7: CERTIFICATE NO.: | E7: ='FORM A'!C8 -> 320 | M7: FOR MONTH : | O7: ='FORM A'!F8 -> 45778
B9: OPERATIONAL STATISTICS: SUBSIDISED SERVICES
D12: ROUTE | F12: TRIPS | L12: Route | M12: KILOMETRES | O12: PASSENGERS | S12: PASSENGER REVENUE | Y12: STANDING
L13: Length | R13: Avg | V13: Avg | W13: Avg | X13: Avg
B14: No | C14: F/R | D14: From | E14: To | F14: Scheduled | G14: DNOs | H14: Late | I14: Break | J14: Non Com | K14: Operated | M14: Scheduled | N14: Operated | O14: Cash | P14: Season | Q14: Total | R14: pass/trip | S14: Cash | T14: Season | U14: Total | V14: rev/trip | W14: rev/rev km | X14: rev/pass | Y14: Trips | Z14: Kilometes
F15: ` | H15: > 30 min. | I15: Down | J15: CRW | M15: (5x11) | N15: (10x11) | Q15: (14+15) | R15: (14/10) | U15: (18+19) | V15: (20/10) | W15: (20/13) | X15: (20/16) | Z15: (24x11)
B16: 1 | C16: =B16+1 -> 2 | D16: =C16+1 -> 3 | E16: =D16+1 -> 4 | F16: =E16+1 -> 5 | G16: =F16+1 -> 6 | H16: =G16+1 -> 7 | I16: =H16+1 -> 8 | J16: =I16+1 -> 9 | ... Z16: =Y16+1 -> 25
A17: =CONCATENATE(B17,C17) -> 10F | B17: 10 | C17: F | D17: BIVA TERMINUS | E17: PONGOLA TERMINUS | F17: =VLOOKUP(A17,'FORM I1 SUB STD NORMAL'!$A$16:$O$55,15,FALSE) -> 26 | K17: =F17-G17-H17-I17-J17-Y17 -> 26 | L17: 101.5 | M17: =F17*L17 -> 2639 | N17: =K17*L17 -> 2639 | O17: 1550 | Q17: =O17+P17 -> 1550 | R17: =Q17/K17 -> 59.615385 | S17: 60120 | U17: =SUM(S17:T17) -> 60120 | V17: =U17/K17 -> 2312.3077 | W17: =U17/N17 -> 22.781357 | X17: =IF(Q17>0,U17/Q17,0) -> 38.787097 | Z17: =SUM(Y17*L17) -> 0 | AA17: =A17 -> 10F | AB17: =IFERROR(VLOOKUP(A17,[1]Sheet7!$A$4:$B$30,2,FALSE),0) -> 0 | AC17: =Y17+AB17 -> 0
A18: =CONCATENATE(B18,C18) -> 10R | B18: 10 | C18: R | D18: PONGOLA TERMINUS | E18: BIVA TERMINUS | F18: =VLOOKUP(A18,'FORM I1 SUB STD NORMAL'!$A$16:$O$55,15,FALSE) -> 26 | K18: =F18-G18-H18-I18-J18-Y18 -> 26 | L18: 101.5 | M18: =F18*L18 -> 2639 | N18: =K18*L18 -> 2639 | O18: 1593 | Q18: =O18+P18 -> 1593 | R18: =Q18/K18 -> 61.269231 | S18: 66107 | U18: =SUM(S18:T18) -> 66107 | V18: =U18/K18 -> 2542.5769 | W18: =U18/N18 -> 25.050019 | X18: =IF(Q18>0,U18/Q18,0) -> 41.498431 | Z18: =SUM(Y18*L18) -> 0 | AA18: =A18 -> 10R | AB18: =IFERROR(VLOOKUP(A18,[1]Sheet7!$A$4:$B$30,2,FALSE),0) -> 1 | AC18: =Y18+AB18 -> 1
A19: =CONCATENATE(B19,C19) -> 1A.3F | B19: 1A.3 | C19: F | D19: INGWAVUMA | E19: MKUZE | F19: =VLOOKUP(A19,'FORM I1 SUB STD NORMAL'!$A$16:$O$55,15,FALSE) -> 5 | K19: =F19-G19-H19-I19-J19-Y19 -> 5 | L19: 73.8 | M19: =F19*L19 -> 369 | N19: =K19*L19 -> 369 | O19: 519 | Q19: =O19+P19 -> 519 | R19: =Q19/K19 -> 103.8 | S19: 11366 | U19: =SUM(S19:T19) -> 11366 | V19: =U19/K19 -> 2273.2 | W19: =U19/N19 -> 30.802168 | X19: =IF(Q19>0,U19/Q19,0) -> 21.899807 | Z19: =SUM(Y19*L19) -> 0 | AA19: =A19 -> 1A.3F | AB19: =IFERROR(VLOOKUP(A19,[1]Sheet7!$A$4:$B$30,2,FALSE),0) -> 0 | AC19: =Y19+AB19 -> 0
A20: =CONCATENATE(B20,C20) -> 1A.3R | B20: 1A.3 | C20: R | D20: MKUZE | E20: INGWAVUMA | F20: =VLOOKUP(A20,'FORM I1 SUB STD NORMAL'!$A$16:$O$55,15,FALSE) -> 5 | K20: =F20-G20-H20-I20-J20-Y20 -> 5 | L20: 73.8 | M20: =F20*L20 -> 369 | N20: =K20*L20 -> 369 | O20: 346 | Q20: =O20+P20 -> 346 | R20: =Q20/K20 -> 69.2 | S20: 6357 | U20: =SUM(S20:T20) -> 6357 | V20: =U20/K20 -> 1271.4 | W20: =U20/N20 -> 17.227642 | X20: =IF(Q20>0,U20/Q20,0) -> 18.372832 | Z20: =SUM(Y20*L20) -> 0 | AA20: =A20 -> 1A.3R | AB20: =IFERROR(VLOOKUP(A20,[1]Sheet7!$A$4:$B$30,2,FALSE),0) -> 0 | AC20: =Y20+AB20 -> 0
A21: =CONCATENATE(B21,C21) -> 1A1F | B21: 1A1 | C21: F | D21: INGWAVUMA | E21: MKUZE | F21: =VLOOKUP(A21,'FORM I1 SUB STD NORMAL'!$A$16:$O$55,15,FALSE) -> 26 | K21: =F21-G21-H21-I21-J21-Y21 -> 26 | L21: 81.8 | M21: =F21*L21 -> 2126.8 | N21: =K21*L21 -> 2126.8 | O21: 1858 | Q21: =O21+P21 -> 1858 | R21: =Q21/K21 -> 71.461538 | S21: 34423.5 | U21: =SUM(S21:T21) -> 34423.5 | V21: =U21/K21 -> 1323.9808 | W21: =U21/N21 -> 16.185584 | X21: =IF(Q21>0,U21/Q21,0) -> 18.52718 | Z21: =SUM(Y21*L21) -> 0 | AA21: =A21 -> 1A1F | AB21: =IFERROR(VLOOKUP(A21,[1]Sheet7!$A$4:$B$30,2,FALSE),0) -> 1 | AC21: =Y21+AB21 -> 1
A22: =CONCATENATE(B22,C22) -> 1A1R | B22: 1A1 | C22: R | D22: MKUZE | E22: INGWAVUMA | F22: =VLOOKUP(A22,'FORM I1 SUB STD NORMAL'!$A$16:$O$55,15,FALSE) -> 26 | K22: =F22-G22-H22-I22-J22-Y22 -> 26 | L22: 90 | M22: =F22*L22 -> 2340 | N22: =K22*L22 -> 2340 | O22: 1796 | Q22: =O22+P22 -> 1796 | R22: =Q22/K22 -> 69.076923 | S22: 33554 | U22: =SUM(S22:T22) -> 33554 | V22: =U22/K22 -> 1290.5385 | W22: =U22/N22 -> 14.339316 | X22: =IF(Q22>0,U22/Q22,0) -> 18.682628 | Z22: =SUM(Y22*L22) -> 0 | AA22: =A22 -> 1A1R | AB22: =IFERROR(VLOOKUP(A22,[1]Sheet7!$A$4:$B$30,2,FALSE),0) -> 1 | AC22: =Y22+AB22 -> 1
A23: =CONCATENATE(B23,C23) -> 1A4F | B23: 1A4 | C23: F | D23: MAVELA | E23: MKUZE | F23: =VLOOKUP(A23,'FORM I1 SUB STD NORMAL'!$A$16:$O$55,15,FALSE) -> 26 | K23: =F23-G23-H23-I23-J23-Y23 -> 26 | L23: 35.8 | M23: =F23*L23 -> 930.8 | N23: =K23*L23 -> 930.8 | O23: 1202 | Q23: =O23+P23 -> 1202 | R23: =Q23/K23 -> 46.230769 | S23: 15116 | U23: =SUM(S23:T23) -> 15116 | V23: =U23/K23 -> 581.38462 | W23: =U23/N23 -> 16.239794 | X23: =IF(Q23>0,U23/Q23,0) -> 12.575707 | Z23: =SUM(Y23*L23) -> 0 | AA23: =A23 -> 1A4F | AB23: =IFERROR(VLOOKUP(A23,[1]Sheet7!$A$4:$B$30,2,FALSE),0) -> 1 | AC23: =Y23+AB23 -> 1
A24: =CONCATENATE(B24,C24) -> 1A4R | B24: 1A4 | C24: R | D24: MKUZE | E24: MAVELA | F24: =VLOOKUP(A24,'FORM I1 SUB STD NORMAL'!$A$16:$O$55,15,FALSE) -> 26 | K24: =F24-G24-H24-I24-J24-Y24 -> 26 | L24: 35.8 | M24: =F24*L24 -> 930.8 | N24: =K24*L24 -> 930.8 | O24: 1202 | Q24: =O24+P24 -> 1202 | R24: =Q24/K24 -> 46.230769 | S24: 14189.5 | U24: =SUM(S24:T24) -> 14189.5 | V24: =U24/K24 -> 545.75 | W24: =U24/N24 -> 15.244413 | X24: =IF(Q24>0,U24/Q24,0) -> 11.804908 | Z24: =SUM(Y24*L24) -> 0 | AA24: =A24 -> 1A4R | AB24: =IFERROR(VLOOKUP(A24,[1]Sheet7!$A$4:$B$30,2,FALSE),0) -> 1 | AC24: =Y24+AB24 -> 1
A25: =CONCATENATE(B25,C25) -> 1B.1F | B25: 1B.1 | C25: F | D25: INGWAVUMA | E25: MKUZE | F25: =VLOOKUP(A25,'FORM I1 SUB STD NORMAL'!$A$16:$O$55,15,FALSE) -> 31 | K25: =F25-G25-H25-I25-J25-Y25 -> 31 | L25: 90 | M25: =F25*L25 -> 2790 | N25: =K25*L25 -> 2790 | O25: 1663 | Q25: =O25+P25 -> 1663 | R25: =Q25/K25 -> 53.645161 | S25: 28845.5 | U25: =SUM(S25:T25) -> 28845.5 | V25: =U25/K25 -> 930.5 | W25: =U25/N25 -> 10.338889 | X25: =IF(Q25>0,U25/Q25,0) -> 17.34546 | Z25: =SUM(Y25*L25) -> 0 | AA25: =A25 -> 1B.1F | AB25: =IFERROR(VLOOKUP(A25,[1]Sheet7!$A$4:$B$30,2,FALSE),0) -> 1 | AC25: =Y25+AB25 -> 1
A26: =CONCATENATE(B26,C26) -> 1B.1R | B26: 1B.1 | C26: R | D26: MKUZE | E26: INGWAVUMA | F26: =VLOOKUP(A26,'FORM I1 SUB STD NORMAL'!$A$16:$O$55,15,FALSE) -> 31 | K26: =F26-G26-H26-I26-J26-Y26 -> 31 | L26: 90 | M26: =F26*L26 -> 2790 | N26: =K26*L26 -> 2790 | O26: 1636 | Q26: =O26+P26 -> 1636 | R26: =Q26/K26 -> 52.774194 | S26: 30412 | U26: =SUM(S26:T26) -> 30412 | V26: =U26/K26 -> 981.03226 | W26: =U26/N26 -> 10.900358 | X26: =IF(Q26>0,U26/Q26,0) -> 18.589242 | Z26: =SUM(Y26*L26) -> 0 | AA26: =A26 -> 1B.1R | AB26: =IFERROR(VLOOKUP(A26,[1]Sheet7!$A$4:$B$30,2,FALSE),0) -> 1 | AC26: =Y26+AB26 -> 1
A27: =CONCATENATE(B27,C27) -> 1B2F | B27: 1B2 | C27: F | D27: INGWAVUMA | E27: MKUZE | F27: =VLOOKUP(A27,'FORM I1 SUB STD NORMAL'!$A$16:$O$55,15,FALSE) -> 26 | K27: =F27-G27-H27-I27-J27-Y27 -> 26 | L27: 85.3 | M27: =F27*L27 -> 2217.8 | N27: =K27*L27 -> 2217.8 | O27: 1576 | Q27: =O27+P27 -> 1576 | R27: =Q27/K27 -> 60.615385 | S27: 24986 | U27: =SUM(S27:T27) -> 24986 | V27: =U27/K27 -> 961 | W27: =U27/N27 -> 11.26612 | X27: =IF(Q27>0,U27/Q27,0) -> 15.854061 | Z27: =SUM(Y27*L27) -> 0 | AA27: =A27 -> 1B2F | AB27: =IFERROR(VLOOKUP(A27,[1]Sheet7!$A$4:$B$30,2,FALSE),0) -> 1 | AC27: =Y27+AB27 -> 1
A28: =CONCATENATE(B28,C28) -> 1B2R | B28: 1B2 | C28: R | D28: MKUZE | E28: INGWAVUMA | F28: =VLOOKUP(A28,'FORM I1 SUB STD NORMAL'!$A$16:$O$55,15,FALSE) -> 26 | K28: =F28-G28-H28-I28-J28-Y28 -> 26 | L28: 85.3 | M28: =F28*L28 -> 2217.8 | N28: =K28*L28 -> 2217.8 | O28: 1765 | Q28: =O28+P28 -> 1765 | R28: =Q28/K28 -> 67.884615 | S28: 27880.5 | U28: =SUM(S28:T28) -> 27880.5 | V28: =U28/K28 -> 1072.3269 | W28: =U28/N28 -> 12.571242 | X28: =IF(Q28>0,U28/Q28,0) -> 15.796317 | Z28: =SUM(Y28*L28) -> 0 | AA28: =A28 -> 1B2R | AB28: =IFERROR(VLOOKUP(A28,[1]Sheet7!$A$4:$B$30,2,FALSE),0) -> 1 | AC28: =Y28+AB28 -> 1
A29: =CONCATENATE(B29,C29) -> 1C1F | B29: 1C1 | C29: F | D29: INGWAVUMA | E29: JOZINI | F29: =VLOOKUP(A29,'FORM I1 SUB STD NORMAL'!$A$16:$O$55,15,FALSE) -> 26 | K29: =F29-G29-H29-I29-J29-Y29 -> 26 | L29: 55.5 | M29: =F29*L29 -> 1443 | N29: =K29*L29 -> 1443 | O29: 1445 | Q29: =O29+P29 -> 1445 | R29: =Q29/K29 -> 55.576923 | S29: 33890 | U29: =SUM(S29:T29) -> 33890 | V29: =U29/K29 -> 1303.4615 | W29: =U29/N29 -> 23.485793 | X29: =IF(Q29>0,U29/Q29,0) -> 23.453287 | Z29: =SUM(Y29*L29) -> 0 | AA29: =A29 -> 1C1F | AB29: =IFERROR(VLOOKUP(A29,[1]Sheet7!$A$4:$B$30,2,FALSE),0) -> 0 | AC29: =Y29+AB29 -> 0
A30: =CONCATENATE(B30,C30) -> 1C1R | B30: 1C1 | C30: R | D30: JOZINI | E30: INGWAVUMA | F30: =VLOOKUP(A30,'FORM I1 SUB STD NORMAL'!$A$16:$O$55,15,FALSE) -> 26 | K30: =F30-G30-H30-I30-J30-Y30 -> 26 | L30: 55.5 | M30: =F30*L30 -> 1443 | N30: =K30*L30 -> 1443 | O30: 1558 | Q30: =O30+P30 -> 1558 | R30: =Q30/K30 -> 59.923077 | S30: 34194 | U30: =SUM(S30:T30) -> 34194 | V30: =U30/K30 -> 1315.1538 | W30: =U30/N30 -> 23.696466 | X30: =IF(Q30>0,U30/Q30,0) -> 21.947368 | Z30: =SUM(Y30*L30) -> 0 | AA30: =A30 -> 1C1R | AB30: =IFERROR(VLOOKUP(A30,[1]Sheet7!$A$4:$B$30,2,FALSE),0) -> 0 | AC30: =Y30+AB30 -> 0
... A34: =CONCATENATE(B34,C34) -> 1DR | B34: 1D | C34: R | D34: KWA-JOHN | E34: INGWAVUMA | F34: =VLOOKUP(A34,'FORM I1 SUB STD NORMAL'!$A$16:$O$55,15,FALSE) -> 21 | K34: =F34-G34-H34-I34-J34-Y34 -> 21 | L34: 30.5 | M34: =F34*L34 -> 640.5 | N34: =K34*L34 -> 640.5 | O34: 948 | Q34: =O34+P34 -> 948 | R34: =Q34/K34 -> 45.142857 | S34: 12177 | U34: =SUM(S34:T34) -> 12177 | V34: =U34/K34 -> 579.85714 | W34: =U34/N34 -> 19.01171 | X34: =IF(Q34>0,U34/Q34,0) -> 12.844937 | Z34: =SUM(Y34*L34) -> 0 | AA34: =A34 -> 1DR | AB34: =IFERROR(VLOOKUP(A34,[1]Sheet7!$A$4:$B$30,2,FALSE),0) -> 0 | AC34: =Y34+AB34 -> 0
A35: =CONCATENATE(B35,C35) -> 2F | B35: 2 | C35: F | D35: ENGONYAMENI | E35: INGWAVUMA | F35: =VLOOKUP(A35,'FORM I1 SUB STD NORMAL'!$A$16:$O$55,15,FALSE) -> 26 | K35: =F35-G35-H35-I35-J35-Y35 -> 26 | L35: 50.2 | M35: =F35*L35 -> 1305.2 | N35: =K35*L35 -> 1305.2 | O35: 4363 | Q35: =O35+P35 -> 4363 | R35: =Q35/K35 -> 167.80769 | S35: 49450 | U35: =SUM(S35:T35) -> 49450 | V35: =U35/K35 -> 1901.9231 | W35: =U35/N35 -> 37.886914 | X35: =IF(Q35>0,U35/Q35,0) -> 11.333945 | Z35: =SUM(Y35*L35) -> 0 | AA35: =A35 -> 2F | AB35: =IFERROR(VLOOKUP(A35,[1]Sheet7!$A$4:$B$30,2,FALSE),0) -> 0 | AC35: =Y35+AB35 -> 0
A36: =CONCATENATE(B36,C36) -> 2R | B36: 2 | C36: R | D36: INGWAVUMA | E36: ENGONYAMENI | F36: =VLOOKUP(A36,'FORM I1 SUB STD NORMAL'!$A$16:$O$55,15,FALSE) -> 26 | K36: =F36-G36-H36-I36-J36-Y36 -> 26 | L36: 50.2 | M36: =F36*L36 -> 1305.2 | N36: =K36*L36 -> 1305.2 | O36: 4237 | Q36: =O36+P36 -> 4237 | R36: =Q36/K36 -> 162.96154 | S36: 43154 | U36: =SUM(S36:T36) -> 43154 | V36: =U36/K36 -> 1659.7692 | W36: =U36/N36 -> 33.063132 | X36: =IF(Q36>0,U36/Q36,0) -> 10.185037 | Z36: =SUM(Y36*L36) -> 0 | AA36: =A36 -> 2R | AB36: =IFERROR(VLOOKUP(A36,[1]Sheet7!$A$4:$B$30,2,FALSE),0) -> 0 | AC36: =Y36+AB36 -> 0
A37: =CONCATENATE(B37,C37) -> 3F | B37: 3 | C37: F | D37: ESIGAYWENI | E37: INGWAVUMA | F37: =VLOOKUP(A37,'FORM I1 SUB STD NORMAL'!$A$16:$O$55,15,FALSE) -> 26 | K37: =F37-G37-H37-I37-J37-Y37 -> 26 | L37: 80.2 | M37: =F37*L37 -> 2085.2 | N37: =K37*L37 -> 2085.2 | O37: 1192 | Q37: =O37+P37 -> 1192 | R37: =Q37/K37 -> 45.846154 | S37: 27704 | U37: =SUM(S37:T37) -> 27704 | V37: =U37/K37 -> 1065.5385 | W37: =U37/N37 -> 13.286016 | X37: =IF(Q37>0,U37/Q37,0) -> 23.241611 | Z37: =SUM(Y37*L37) -> 0 | AA37: =A37 -> 3F | AB37: =IFERROR(VLOOKUP(A37,[1]Sheet7!$A$4:$B$30,2,FALSE),0) -> 0 | AC37: =Y37+AB37 -> 0
A38: =CONCATENATE(B38,C38) -> 3R | B38: 3 | C38: R | D38: INGWAVUMA | E38: ESIGAYWENI | F38: =VLOOKUP(A38,'FORM I1 SUB STD NORMAL'!$A$16:$O$55,15,FALSE) -> 26 | K38: =F38-G38-H38-I38-J38-Y38 -> 26 | L38: 80.2 | M38: =F38*L38 -> 2085.2 | N38: =K38*L38 -> 2085.2 | O38: 1221 | Q38: =O38+P38 -> 1221 | R38: =Q38/K38 -> 46.961538 | S38: 27079 | U38: =SUM(S38:T38) -> 27079 | V38: =U38/K38 -> 1041.5 | W38: =U38/N38 -> 12.986284 | X38: =IF(Q38>0,U38/Q38,0) -> 22.177723 | Z38: =SUM(Y38*L38) -> 0 | AA38: =A38 -> 3R | AB38: =IFERROR(VLOOKUP(A38,[1]Sheet7!$A$4:$B$30,2,FALSE),0) -> 0 | AC38: =Y38+AB38 -> 0
A39: =CONCATENATE(B39,C39) -> 5F | B39: 5 | C39: F | D39: EKUKHANYENI | E39: MKUZE | F39: =VLOOKUP(A39,'FORM I1 SUB STD NORMAL'!$A$16:$O$55,15,FALSE) -> 26 | K39: =F39-G39-H39-I39-J39-Y39 -> 25 | L39: 117 | M39: =F39*L39 -> 3042 | N39: =K39*L39 -> 2925 | O39: 1603 | Q39: =O39+P39 -> 1603 | R39: =Q39/K39 -> 64.12 | S39: 29349 | U39: =SUM(S39:T39) -> 29349 | V39: =U39/K39 -> 1173.96 | W39: =U39/N39 -> 10.033846 | X39: =IF(Q39>0,U39/Q39,0) -> 18.308796 | Y39: 1 | Z39: =SUM(Y39*L39) -> 117 | AA39: =A39 -> 5F | AB39: =IFERROR(VLOOKUP(A39,[1]Sheet7!$A$4:$B$30,2,FALSE),0) -> 1 | AC39: =Y39+AB39 -> 2
A40: =CONCATENATE(B40,C40) -> 5R | B40: 5 | C40: R | D40: MKUZE | E40: EKUKHANYENI | F40: =VLOOKUP(A40,'FORM I1 SUB STD NORMAL'!$A$16:$O$55,15,FALSE) -> 26 | K40: =F40-G40-H40-I40-J40-Y40 -> 25 | L40: 117 | M40: =F40*L40 -> 3042 | N40: =K40*L40 -> 2925 | O40: 1636 | Q40: =O40+P40 -> 1636 | R40: =Q40/K40 -> 65.44 | S40: 31854 | U40: =SUM(S40:T40) -> 31854 | V40: =U40/K40 -> 1274.16 | W40: =U40/N40 -> 10.890256 | X40: =IF(Q40>0,U40/Q40,0) -> 19.47066 | Y40: 1 | Z40: =SUM(Y40*L40) -> 117 | AA40: =A40 -> 5R | AB40: =IFERROR(VLOOKUP(A40,[1]Sheet7!$A$4:$B$30,2,FALSE),0) -> 1 | AC40: =Y40+AB40 -> 2
A41: =CONCATENATE(B41,C41) -> 6AF | B41: 6A | C41: F | D41: MANGUZE | E41: MKUZE | F41: =VLOOKUP(A41,'FORM I1 SUB STD NORMAL'!$A$16:$O$55,15,FALSE) -> 36 | K41: =F41-G41-H41-I41-J41-Y41 -> 36 | L41: 149.9 | M41: =F41*L41 -> 5396.4 | N41: =K41*L41 -> 5396.4 | O41: 1428 | Q41: =O41+P41 -> 1428 | R41: =Q41/K41 -> 39.666667 | S41: 32903.5 | U41: =SUM(S41:T41) -> 32903.5 | V41: =U41/K41 -> 913.98611 | W41: =U41/N41 -> 6.0973056 | X41: =IF(Q41>0,U41/Q41,0) -> 23.041667 | Z41: =SUM(Y41*L41) -> 0 | AA41: =A41 -> 6AF | AB41: =IFERROR(VLOOKUP(A41,[1]Sheet7!$A$4:$B$30,2,FALSE),0) -> 1 | AC41: =Y41+AB41 -> 1
A42: =CONCATENATE(B42,C42) -> 6AR | B42: 6A | C42: R | D42: MKUZE | E42: MANGUZE | F42: =VLOOKUP(A42,'FORM I1 SUB STD NORMAL'!$A$16:$O$55,15,FALSE) -> 26 | K42: =F42-G42-H42-I42-J42-Y42 -> 26 | L42: 149.9 | M42: =F42*L42 -> 3897.4 | N42: =K42*L42 -> 3897.4 | O42: 1382 | Q42: =O42+P42 -> 1382 | R42: =Q42/K42 -> 53.153846 | S42: 31723.5 | U42: =SUM(S42:T42) -> 31723.5 | V42: =U42/K42 -> 1220.1346 | W42: =U42/N42 -> 8.1396572 | X42: =IF(Q42>0,U42/Q42,0) -> 22.954776 | Z42: =SUM(Y42*L42) -> 0 | AA42: =A42 -> 6AR | AB42: =IFERROR(VLOOKUP(A42,[1]Sheet7!$A$4:$B$30,2,FALSE),0) -> 1 | AC42: =Y42+AB42 -> 1
A43: =CONCATENATE(B43,C43) -> 6BF | B43: 6B | C43: F | D43: MBUYISA | E43: MKUZE | F43: =VLOOKUP(A43,'FORM I1 SUB STD NORMAL'!$A$16:$O$55,15,FALSE) -> 21 | K43: =F43-G43-H43-I43-J43-Y43 -> 21 | L43: 97.5 | M43: =F43*L43 -> 2047.5 | N43: =K43*L43 -> 2047.5 | O43: 978 | Q43: =O43+P43 -> 978 | R43: =Q43/K43 -> 46.571429 | S43: 27186 | U43: =SUM(S43:T43) -> 27186 | V43: =U43/K43 -> 1294.5714 | W43: =U43/N43 -> 13.277656 | X43: =IF(Q43>0,U43/Q43,0) -> 27.797546 | Z43: =SUM(Y43*L43) -> 0 | AA43: =A43 -> 6BF | AB43: =IFERROR(VLOOKUP(A43,[1]Sheet7!$A$4:$B$30,2,FALSE),0) -> 1 | AC43: =Y43+AB43 -> 1
A44: =CONCATENATE(B44,C44) -> 6BR | B44: 6B | C44: R | D44: MKUZE | E44: MBUYISA | F44: =VLOOKUP(A44,'FORM I1 SUB STD NORMAL'!$A$16:$O$55,15,FALSE) -> 26 | K44: =F44-G44-H44-I44-J44-Y44 -> 26 | L44: 97.5 | M44: =F44*L44 -> 2535 | N44: =K44*L44 -> 2535 | O44: 1165 | Q44: =O44+P44 -> 1165 | R44: =Q44/K44 -> 44.807692 | S44: 25938 | U44: =SUM(S44:T44) -> 25938 | V44: =U44/K44 -> 997.61538 | W44: =U44/N44 -> 10.231953 | X44: =IF(Q44>0,U44/Q44,0) -> 22.264378 | Z44: =SUM(Y44*L44) -> 0 | AA44: =A44 -> 6BR | AB44: =IFERROR(VLOOKUP(A44,[1]Sheet7!$A$4:$B$30,2,FALSE),0) -> 1 | AC44: =Y44+AB44 -> 1
A45: =CONCATENATE(B45,C45) -> 6CF | B45: 6C | C45: F | D45: JOZINI | E45: MKUZE | F45: =VLOOKUP(A45,'FORM I1 SUB STD NORMAL'!$A$16:$O$55,15,FALSE) -> 26 | K45: =F45-G45-H45-I45-J45-Y45 -> 26 | L45: 41 | M45: =F45*L45 -> 1066 | N45: =K45*L45 -> 1066 | O45: 1198 | Q45: =O45+P45 -> 1198 | R45: =Q45/K45 -> 46.076923 | S45: 16324 | U45: =SUM(S45:T45) -> 16324 | V45: =U45/K45 -> 627.84615 | W45: =U45/N45 -> 15.313321 | X45: =IF(Q45>0,U45/Q45,0) -> 13.626043 | Z45: =SUM(Y45*L45) -> 0 | AA45: =A45 -> 6CF | AB45: =IFERROR(VLOOKUP(A45,[1]Sheet7!$A$4:$B$30,2,FALSE),0) -> 1 | AC45: =Y45+AB45 -> 1
A46: =CONCATENATE(B46,C46) -> 6CR | B46: 6C | C46: R | D46: MKUZE | E46: JOZINI | F46: =VLOOKUP(A46,'FORM I1 SUB STD NORMAL'!$A$16:$O$55,15,FALSE) -> 26 | K46: =F46-G46-H46-I46-J46-Y46 -> 26 | L46: 41 | M46: =F46*L46 -> 1066 | N46: =K46*L46 -> 1066 | O46: 1175 | Q46: =O46+P46 -> 1175 | R46: =Q46/K46 -> 45.192308 | S46: 13250 | U46: =SUM(S46:T46) -> 13250 | V46: =U46/K46 -> 509.61538 | W46: =U46/N46 -> 12.429644 | X46: =IF(Q46>0,U46/Q46,0) -> 11.276596 | Z46: =SUM(Y46*L46) -> 0 | AA46: =A46 -> 6CR | AB46: =IFERROR(VLOOKUP(A46,[1]Sheet7!$A$4:$B$30,2,FALSE),0) -> 1 | AC46: =Y46+AB46 -> 1
A47: =CONCATENATE(B47,C47) -> 7AF | B47: 7A | C47: F | D47: MANGUZE | E47: MKUZE | F47: =VLOOKUP(A47,'FORM I1 SUB STD NORMAL'!$A$16:$O$55,15,FALSE) -> 21 | K47: =F47-G47-H47-I47-J47-Y47 -> 21 | L47: 136.5 | M47: =F47*L47 -> 2866.5 | N47: =K47*L47 -> 2866.5 | O47: 960 | Q47: =O47+P47 -> 960 | R47: =Q47/K47 -> 45.714286 | S47: 17323.5 | U47: =SUM(S47:T47) -> 17323.5 | V47: =U47/K47 -> 824.92857 | W47: =U47/N47 -> 6.0434328 | X47: =IF(Q47>0,U47/Q47,0) -> 18.045313 | Z47: =SUM(Y47*L47) -> 0 | AA47: =A47 -> 7AF | AB47: =IFERROR(VLOOKUP(A47,[1]Sheet7!$A$4:$B$30,2,FALSE),0) -> 1 | AC47: =Y47+AB47 -> 1
A48: =CONCATENATE(B48,C48) -> 7AR | B48: 7A | C48: R | D48: MKUZE | E48: MANGUZE | F48: =VLOOKUP(A48,'FORM I1 SUB STD NORMAL'!$A$16:$O$55,15,FALSE) -> 26 | K48: =F48-G48-H48-I48-J48-Y48 -> 26 | L48: 136.5 | M48: =F48*L48 -> 3549 | N48: =K48*L48 -> 3549 | O48: 1179 | Q48: =O48+P48 -> 1179 | R48: =Q48/K48 -> 45.346154 | S48: 17371.5 | U48: =SUM(S48:T48) -> 17371.5 | V48: =U48/K48 -> 668.13462 | W48: =U48/N48 -> 4.8947591 | X48: =IF(Q48>0,U48/Q48,0) -> 14.734097 | Z48: =SUM(Y48*L48) -> 0 | AA48: =A48 -> 7AR | AB48: =IFERROR(VLOOKUP(A48,[1]Sheet7!$A$4:$B$30,2,FALSE),0) -> 1 | AC48: =Y48+AB48 -> 1
A49: =CONCATENATE(B49,C49) -> 7CF | B49: 7C | C49: F | D49: NGUTSHANA | E49: MKUZE | F49: =VLOOKUP(A49,'FORM I1 SUB STD NORMAL'!$A$16:$O$55,15,FALSE) -> 31 | K49: =F49-G49-H49-I49-J49-Y49 -> 31 | L49: 117.5 | M49: =F49*L49 -> 3642.5 | N49: =K49*L49 -> 3642.5 | O49: 1380 | Q49: =O49+P49 -> 1380 | R49: =Q49/K49 -> 44.516129 | S49: 23729.5 | U49: =SUM(S49:T49) -> 23729.5 | V49: =U49/K49 -> 765.46774 | W49: =U49/N49 -> 6.5146191 | X49: =IF(Q49>0,U49/Q49,0) -> 17.19529 | Z49: =SUM(Y49*L49) -> 0 | AA49: =A49 -> 7CF | AB49: =IFERROR(VLOOKUP(A49,[1]Sheet7!$A$4:$B$30,2,FALSE),0) -> 1 | AC49: =Y49+AB49 -> 1
...

Sheet FORM F2 UNSUB - STD BUS 
B1: FORM F2 - STANDARD BUS
B3: PUBLIC TRANSPORT : | E3: ='FORM F1 SUB - STD BUS'!E3 -> PROVISION OF PUBLIC PASSENGER TRANSPORT MKUZE AND SURROUNDING
B5: ='FORM F1 SUB - STD BUS'!B5 -> CONTRACT : ZNT 1129 | M5: OPERATOR : | O5: ='FORM F1 SUB - STD BUS'!O5 -> Ripple Effect 40 (Pty) Ltd
B7: CERTIFICATE NO.: | E7: ='FORM F1 SUB - STD BUS'!E7 -> 320 | M7: FOR MONTH : | O7: ='FORM F1 SUB - STD BUS'!O7 -> 45778
B9: OPERATIONAL STATISTICS: UNSUBSIDISED SERVICES
D12: ROUTE | F12: TRIPS | L12: Route | M12: KILOMETRES | O12: PASSENGERS | S12: PASSENGER REVENUE | Y12: STANDING
L13: Length | R13: Avg | V13: Avg | W13: Avg | X13: Avg
B14: No | C14: F/R | D14: From | E14: To | F14: Scheduled | G14: DNOs | H14: Late | I14: Break | J14: Non Com | K14: Operated | M14: Scheduled | N14: Operated | O14: Cash | P14: Season | Q14: Total | R14: pass/trip | S14: Cash | T14: Season | U14: Total | V14: rev/trip | W14: rev/rev km | X14: rev/pass | Y14: Trips | Z14: Kilometes
F15: ` | H15: > 30 min. | I15: Down | J15: CRW | M15: (5x11) | N15: (10x11) | Q15: (14+15) | R15: (14/10) | U15: (18+19) | V15: (20/10) | W15: (20/13) | X15: (20/16) | Z15: (24x11)
B16: 1 | C16: =B16+1 -> 2 | D16: =C16+1 -> 3 | E16: =D16+1 -> 4 | F16: =E16+1 -> 5 | G16: =F16+1 -> 6 | H16: =G16+1 -> 7 | I16: =H16+1 -> 8 | J16: =I16+1 -> 9 | ... Z16: =Y16+1 -> 25
A17: =CONCATENATE(B17,C17) -> 4R | B17: 4 | C17: R | D17: MANGUZI | E17: INGWAVUMA | F17: =VLOOKUP(B17,'FORM I2 UNSUB STD '!$B$16:$O$20,14,FALSE) -> 42 | K17: =F17-G17-H17-I17-J17-Y17 -> 42 | L17: 98.9 | M17: =F17*L17 -> 4153.8 | N17: =K17*L17 -> 4153.8 | O17: 1896 | Q17: =O17+P17 -> 1896 | R17: =Q17/K17 -> 45.142857 | S17: 16002.5 | U17: =SUM(S17:T17) -> 16002.5 | V17: =U17/K17 -> 381.0119 | W17: =U17/N17 -> 3.8524965 | X17: =IF(Q17>0,U17/Q17,0) -> 8.4401371 | Z17: =SUM(Y17*L17) -> 0
A18: =CONCATENATE(B18,C18) -> 8F | B18: 8 | C18: F | D18: MANABA | E18: MKUZE | F18: =VLOOKUP(B18,'FORM I2 UNSUB STD '!$B$16:$O$20,14,FALSE) -> 10 | K18: =F18-G18-H18-I18-J18-Y18 -> 10 | L18: 78.8 | M18: =F18*L18 -> 788 | N18: =K18*L18 -> 788 | O18: 452 | Q18: =O18+P18 -> 452 | R18: =Q18/K18 -> 45.2 | S18: 5846 | U18: =SUM(S18:T18) -> 5846 | V18: =U18/K18 -> 584.6 | W18: =U18/N18 -> 7.4187817 | X18: =IF(Q18>0,U18/Q18,0) -> 12.933628 | Z18: =SUM(Y18*L18) -> 0
A19: =CONCATENATE(B19,C19) -> 11AR | B19: 11A | C19: R | D19: MKUZE | E19: EMPANGENI | F19: =VLOOKUP(B19,'FORM I2 UNSUB STD '!$B$16:$O$20,14,FALSE) -> 42 | K19: =F19-G19-H19-I19-J19-Y19 -> 42 | L19: 125.6 | M19: =F19*L19 -> 5275.2 | N19: =K19*L19 -> 5275.2 | O19: 1903 | Q19: =O19+P19 -> 1903 | R19: =Q19/K19 -> 45.309524 | S19: 44034.5 | U19: =SUM(S19:T19) -> 44034.5 | V19: =U19/K19 -> 1048.4405 | W19: =U19/N19 -> 8.347456 | X19: =IF(Q19>0,U19/Q19,0) -> 23.139517 | Z19: =SUM(Y19*L19) -> 0
A20: =CONCATENATE(B20,C20) -> 11BF | B20: 11B | C20: F | D20: MANABA | E20: EMPANGENI | F20: =VLOOKUP(B20,'FORM I2 UNSUB STD '!$B$16:$O$20,14,FALSE) -> 18 | K20: =F20-G20-H20-I20-J20-Y20 -> 18 | L20: 224.9 | M20: =F20*L20 -> 4048.2 | N20: =K20*L20 -> 4048.2 | Q20: =O20+P20 -> 0 | R20: =Q20/K20 -> 0 | U20: =SUM(S20:T20) -> 0 | V20: =U20/K20 -> 0 | W20: =U20/N20 -> 0 | X20: =IF(Q20>0,U20/Q20,0) -> 0 | Z20: =SUM(Y20*L20) -> 0
A21: =CONCATENATE(B21,C21) -> 19AR | B21: 19A | C21: R | D21: MKUZE | E21: MHLEKAZI | F21: =VLOOKUP(B21,'FORM I2 UNSUB STD '!$B$16:$O$20,14,FALSE) -> 52 | K21: =F21-G21-H21-I21-J21-Y21 -> 52 | L21: 40 | M21: =F21*L21 -> 2080 | N21: =K21*L21 -> 2080 | O21: 2384 | Q21: =O21+P21 -> 2384 | R21: =Q21/K21 -> 45.846154 | S21: 26407.5 | U21: =SUM(S21:T21) -> 26407.5 | V21: =U21/K21 -> 507.83654 | W21: =U21/N21 -> 12.695913 | X21: =IF(Q21>0,U21/Q21,0) -> 11.076971 | Z21: =SUM(Y21*L21) -> 0
B23: TOTALS TO FORM E | F23: =SUM(F17:F21) -> 164 | G23: =SUM(G17:G21) -> 0 | H23: =SUM(H17:H21) -> 0 | I23: =SUM(I17:I21) -> 0 | J23: =SUM(J17:J21) -> 0 | K23: =SUM(K17:K21) -> 164 | M23: =SUM(M17:M21) -> 16345.2 | N23: =SUM(N17:N21) -> 16345.2 | O23: =SUM(O17:O21) -> 6635 | P23: =SUM(P17:P21) -> 0 | Q23: =SUM(Q17:Q21) -> 6635 | R23: =Q23/K23 -> 40.457317 | S23: =SUM(S17:S21) -> 92290.5 | T23: =SUM(T17:T21) -> 0 | U23: =SUM(U17:U21) -> 92290.5 | V23: =U23/K23 -> 562.74695 | W23: =U23/N23 -> 5.6463365 | X23: =IF(Q23>0,U23/Q23,0) -> 13.909646 | Y23: =SUM(Y17:Y21) -> 0 | Z23: =SUM(Z17:Z21) -> 0
J31: =I32-N23 -> 141384
H32: ='[2]FORM I1 SUB STD NORMAL'!N186+'[2]FORM I1 SUB STD SCHOOL H'!N183+'[2]FORM I1 SUB STD PUBLIC HOLIDAY'!O186 -> 4282 | I32: ='[2]FORM I1 SUB STD NORMAL'!O186+'[2]FORM I1 SUB STD SCHOOL H'!O183+'[2]FORM I1 SUB STD PUBLIC HOLIDAY'!P186 -> 157729.2

Sheet FORM G1
A1: FORM G1 - DETAILS OF PENALTIES
A3: PUBLIC TRANSPORT : | E3: ='FORM A'!C3 -> PROVISION OF PUBLIC PASSENGER TRANSPORT MKUZE AND SURROUNDING
A5: ='FORM A'!A6 -> CONTRACT : ZNT 1129 | I5: OPERATOR : | J5: ='FORM A'!F6 -> Ripple Effect 40 (Pty) Ltd
A7: PAYMENT CERTIFICATE NO.: | E7: ='FORM A'!C8 -> 320 | I7: FOR MONTH: | J7: ='FORM A'!F8 -> 45778
A9: LIST OF MONTHLY PENALTIES:
A11: Date | B11: Route | C11: Shift | D11: Bus | E11: TIME | H11: Place | I11: ROUTE | K11: Penalty | L11: Route | M11: RATE | N11: Penalty | O11: Penalty | P11: Displayed | Q11: Ref
B12: Number | C12: Number | D12: Number | E12: Sched | F12: CH-P | G12: Actual | I12: From | J12: To | K12: Code | L12: Length | M12: (R) | N12: (%) | O12: (R) | Q12: No
A13: 1 | B13: 2 | C13: 3 | D13: 4 | E13: 5 | F13: 6 | G13: 7 | H13: 8 | I13: 9 | J13: 10 | K13: 11 | L13: 12 | M13: 13 | N13: 14 | O13: 15 | P13: 16 | Q13: 17
A14: 45779 | B14: 9a | C14: 25 | D14: 1021 | E14: 12:h00 | F14: 12:h00 | G14: 12:h10 | H14: MKUZE | I14: mkuze | J14: mazibuko | K14: 2 | L14: =VLOOKUP(B14,'FORM F1 SUB - STD BUS'!$B$17:L56,11,FALSE) -> 70.3 | M14: 8.21 | N14: 0.25 | O14: =ROUND(L14*M14*N14,2) -> 144.29 | Q14: OP
A15: 45779 | B15: 9b | C15: 26 | D15: 1007 | E15: 14:h00 | F15: 14:h00 | G15: 14:h13 | H15: MKUZE | I15: mkuze | J15: hlabisa | K15: 2 | L15: =VLOOKUP(B15,'FORM F1 SUB - STD BUS'!$B$17:L57,11,FALSE) -> 78 | M15: 8.21 | N15: 0.25 | O15: =ROUND(L15*M15*N15,2) -> 160.1 | Q15: OP
A16: 45782 | B16: 8 | C16: 24 | D16: 1026 | E16: 12:h30 | F16: 12:h30 | G16: 12:h40 | H16: MKUZE | I16: mkuze | J16: manaba | K16: 2 | L16: =VLOOKUP(B16,'FORM F1 SUB - STD BUS'!$B$17:L58,11,FALSE) -> 78.8 | M16: 8.21 | N16: 0.25 | O16: =ROUND(L16*M16*N16,2) -> 161.74 | Q16: OP
A17: 45786 | B17: 1a1 | C17: 2 | D17: 1019 | E17: 14:h00 | F17: 14:h00 | G17: 14:h13 | H17: MKUZE | I17: mkuze | J17: emachobeni | K17: 2 | L17: =VLOOKUP(B17,'FORM F1 SUB - STD BUS'!$B$17:L62,11,FALSE) -> 81.8 | M17: 8.21 | N17: 0.25 | O17: =ROUND(L17*M17*N17,2) -> 167.89 | Q17: TESS/OP
A18: 45790 | B18: 8 | C18: 24 | D18: 1025 | E18: 12:h30 | F18: 12:h30 | G18: 12:h44 | H18: MKUZE | I18: mkuze | J18: manaba | K18: 2 | L18: =VLOOKUP(B18,'FORM F1 SUB - STD BUS'!$B$17:L63,11,FALSE) -> 78.8 | M18: 8.21 | N18: 0.25 | O18: =ROUND(L18*M18*N18,2) -> 161.74 | Q18: TESS/OP
A19: 45798 | B19: 9b | C19: 26 | D19: 1028 | E19: 14:h00 | F19: 14:h00 | G19: 14:h10 | H19: MKUZE | I19: mkuze | J19: hlabisa | K19: 2 | L19: =VLOOKUP(B19,'FORM F1 SUB - STD BUS'!$B$17:L60,11,FALSE) -> 78 | M19: 8.21 | N19: 0.25 | O19: =ROUND(L19*M19*N19,2) -> 160.1 | Q19: OP
